Workbook

Sheet 總資產
A1: 新台幣 | E1: 美元 | I1: 台股 | M1: 美股 | Q1: 加密貨幣
A2: 永豐大戶活存 | C2: 201256 | E2: 美元活存 | G2: 220 | I2: 006208 | K2: ='006208'!D3*'006208'!C3*0.997 | M2: VT | O2: =VT!H3*VT!D3 | Q2: BTC | S2: =(682.1+1166.72+328.25)*投資!G2
A3: 玉山銀行活存 | C3: 11601 | E3: Chase | G3: 0 | I3: 2890 | K3: ='2890'!D3*'2890'!C3*0.997 | M3: VOO | O3: =VOO!C3*VOO!D3 | Q3: ETH | S3: =234.83*投資!G2
A4: 一銀iLeo活存 | C4: 150039 | E4: Ether.fi | G4: 3 | Q4: SOL | S4: =309.82*投資!G2
A5: 中華郵政活存 | C5: 550 | Q5: SUI | S5: =15.45*投資!G2
A6: 中國信託活存 | C6: 700 | Q6: USDT | S6: =(502.19+483.32+301.6+2206.02+151.975)*投資!G2
A7: 華南Sny活存 | C7: 100189 | Q7: USDC | S7: =(501.74+500.68)*投資!G2
A8: 定存 | C8: 60000
A9: 錢包 | C9: 800
A10: 總計 | C10: =SUM(C2:D9) | E10: 總計 | G10: =SUM(G2:H9)*投資!G2 | I10: 總計 | K10: =SUM(K2:L9) | M10: 總計 | O10: =SUM(O2:P9) | Q10: 總計 | S10: =SUM(S2:T9)
A11: 總資產 | C11: 負債
A12: =C10+G10+K10+O10+S10 | C12: =12012
A14: 淨資產 | C14: 負債率
A16: =A12-C12 | C16: =C12/A12

Sheet 投資
A1: 台股 | E1: 折讓款 | F1: 交易稅 | G1: 匯率
A2: 總成本 | B2: 總現值 | C2: 報酬率(含息) | E2: 304 | F2: 0 | G2: 32.379
A3: =('006208'!E3+'00692'!E3+'2890'!E3)-('006208'!F3+'00692'!F3+'2890'!F3)-E2+7345 | B3: =總資產!K10 | C3: =C4/A3
C4: =B3-A3
A8: 美股 | E8: Total
A9: 總成本 | B9: 總現值 | C9: 報酬率(含息) | E9: 總成本 | F9: 總現值 | G9: 報酬率(含息)
A10: =(BND!E3+VT!E3)-(BND!F3+VT!F3) | B10: =總資產!O10 | C10: =C11/A10 | E10: =A3+A10+A17 | F10: =B3+B10+B17 | G10: =G11/E10
C11: =B10-A10 | G11: =F10-E10
A15: 加密貨幣
A16: 總成本 | B16: 總現值 | C16: 報酬率(含息)
A17: 253581 | B17: =總資產!S10 | C17: =C18/A17
C18: =B17-A17

Sheet 006208
C1: 存股統計專用表格 | F1: 006208.TW
A2: 實際成本 | B2: 帳面成本 | C2: 目前市價 | D2: 總股數 | E2: 總成本 | F2: 股利+借券 | G2: 報酬率(含息)
A3: =(E3-F3)/D3 | B3: =E3/D3 | C3: 247.6 | D3: =SUM(D7:D505) | E3: =SUM(E7:E505) | F3: =SUM(F6:G505) | G3: =G4/E3
G4: =D3*C3-E3+F3
A5: 交易筆數 | B5: 購買日期 | C5: 購入價格 | D5: 股數 | E5: 持有成本 | F5: 股利
A6: 1 | B6: 借券收入
A7: 2 | B7: 2023.07.17 | C7: 76.47 | D7: 6 | E7: 459
A8: 3 | B8: 2023.07.21 | C8: 73.65 | D8: 20 | E8: 1475
A9: 4 | B9: 2023.08.07 | C9: 74.3 | D9: 40 | E9: 2976
A10: 5 | B10: 2023.08.09 | C10: 73.56 | D10: 20 | E10: 1472
A11: 6 | B11: 2023.09.11 | C11: 71.61 | D11: 21 | E11: 1505
A12: 7 | B12: 2023.10.06 | C12: 71.85 | D12: 21 | E12: 1510
A13: 8 | B13: 2023.10.26 | C13: 70.75 | D13: 30 | E13: 2125
A14: 9 | B14: 2023.11.06 | C14: 73.23 | D14: 21 | E14: 1539
A15: 10 | B15: 2023.12.06 | C15: 74.8 | D15: 20 | E15: 1497
A16: 11 | B16: 2023.12.12 | C16: 0 | D16: 0 | E16: 0 | F16: 152
A17: 12 | B17: 2023.12.12 | C17: 75.15 | D17: 20 | E17: 1505
A18: 13 | B18: 2024.01.08 | C18: 75.95 | D18: 20 | E18: 1520
A19: 14 | B19: 2024.02.01 | C19: 78.15 | D19: 20 | E19: 1565
A20: 15 | B20: 2024.02.15 | C20: 82.89 | D20: 19 | E20: 1576
A21: 16 | B21: 2024.03.06 | C21: 86.59 | D21: 17 | E21: 1473
A22: 17 | B22: 2024.04.08 | C22: 93.25 | D22: 16 | E22: 1493
A23: 18 | B23: 2024.05.06 | C23: 93.53 | D23: 17 | E23: 1591
A24: 19 | B24: 2024.06.06 | C24: 101.93 | D24: 15 | E24: 1530
A25: 20 | B25: 2024.07.08 | C25: 115.31 | D25: 13 | E25: 1500
A26: 21 | B26: 2024.08.06 | C26: 97.13 | D26: 16 | E26: 1555
A27: 22 | B27: 2024.08.09 | C27: 0 | D27: 0 | E27: 0 | F27: 279
A28: 23 | B28: 2024.08.16 | C28: 107 | D28: 1 | E28: 108
A29: 24 | B29: 2024.09.06 | C29: 102.07 | D29: 15 | E29: 1532
A30: 25 | B30: 2024.10.07 | C30: 109.64 | D30: 14 | E30: 1535
A31: 26 | B31: 2024.11.06 | C31: 114.77 | D31: 13 | E31: 1493
A32: 27 | B32: 2024.12.06 | C32: 113.64 | D32: 14 | E32: 1592
A33: 28 | B33: 2024.12.12 | C33: 0 | D33: 0 | E33: 0 | F33: 374
A34: 29 | B34: 2024.12.19 | C34: 112.5 | D34: 2 | E34: 226
A35: 30 | B35: 2025.01.06 | C35: 116.46 | D35: 13 | E35: 1515
A36: 31 | B36: 2025.02.06 | C36: 116.15 | D36: 13 | E36: 1511
A37: 32 | B37: 2025.02.06 | C37: 116.35 | D37: 100 | E37: 10814
A38: 33 | B38: 2025.03.06 | C38: 110.44 | D38: 18 | E38: 1989
A39: 34 | B39: 2025.04.07 | C39: 93.32 | D39: 22 | E39: 2054
A40: 35 | B40: 2025.05.06 | C40: 100.5 | D40: 20 | E40: 2011
...

Sheet 2890
C1: 存股統計專用表格 | F1: 2890.TW
A2: 實際成本 | B2: 帳面成本 | C2: 目前市價 | D2: 總股數 | E2: 總成本 | F2: 股利+借券 | G2: 報酬率(含息)
A3: =(E3-F3)/D3 | B3: =E3/D3 | C3: 45.4 | D3: =SUM(D7:D505) | E3: =SUM(E7:E505) | F3: =SUM(F6:G505) | G3: =G4/E3
G4: =D3*C3-E3+F3
A5: 交易筆數 | B5: 購買日期 | C5: 購入價格 | D5: 股數 | E5: 持有成本 | F5: 股利
A6: 1 | B6: 借券收入
A7: 2 | B7: 2023.08.07 | C7: 18.7 | D7: 2000 | E7: 37453
A8: 3 | B8: 2023.08.09 | C8: 18 | D8: 65 | E8: 1171
A9: 4 | B9: 2023.08.09 | C9: 17.93 | D9: 50 | E9: 897
A10: 5 | B10: 2023.08.18 | C10: 17.1 | D10: 1000 | E10: 17124
A11: 6 | B11: 2023.09.11 | C11: 17.26 | D11: 50 | E11: 864
A12: 7 | B12: 2023.09.13 | C12: 0 | D12: 40 | E12: 0 | F12: 1200
A13: 8 | B13: 2023.10.06 | C13: 17.62 | D13: 50 | E13: 882
A14: 9 | B14: 2023.10.25 | C14: 18.1 | D14: 100 | E14: 1812
A15: 10 | B15: 2023.10.31 | C15: 17.8 | D15: 30 | E15: 535
A16: 11 | B16: 2023.11.06 | C16: 18.51 | D16: 47 | E16: 871
A17: 12 | B17: 2023.12.06 | C17: 19.29 | D17: 45 | E17: 869
A18: 13 | B18: 2023.12.07 | C18: 19.15 | D18: 45 | E18: 862
A19: 14 | B19: 2024.01.08 | C19: 19.61 | D19: 44 | E19: 864
A20: 15 | B20: 2024.02.15 | C20: 19.42 | D20: 45 | E20: 875
A21: 16 | B21: 2024.03.06 | C21: 20.05 | D21: 43 | E21: 863
A22: 17 | B22: 2024.04.08 | C22: 21.44 | D22: 41 | E22: 880
A23: 18 | B23: 2024.05.06 | C23: 22.51 | D23: 39 | E23: 879
A24: 19 | B24: 2024.06.06 | C24: 23.21 | D24: 38 | E24: 883
... A27: 22 | B27: 2024.09.06 | C27: 23.5 | D27: 38 | E27: 894
A28: 23 | B28: 2024.09.27 | C28: 0 | D28: 96 | E28: 0 | F28: 2880
A29: 24 | B29: 2024.10.07 | C29: 24.08 | D29: 37 | E29: 891
A30: 25 | B30: 2024.10.17 | C30: 23.65 | D30: 63 | E30: 1491
A31: 26 | B31: 2024.10.21 | C31: 23.65 | D31: 59 | E31: 1395
A32: 27 | B32: 2024.11.06 | C32: 22.77 | D32: 39 | E32: 889
A33: 28 | B33: 2024.12.06 | C33: 24.42 | D33: 36 | E33: 880
A34: 29 | B34: 2025.01.06 | C34: 23.11 | D34: 38 | E34: 879
A35: 30 | B35: 2025.02.06 | C35: 22.54 | D35: 39 | E35: 880
A36: 31 | B36: 2025.03.06 | C36: 22.74 | D36: 39 | E36: 888
A37: 32 | B37: 2025.04.07 | C37: 20.3 | D37: 44 | E37: 894
A38: 33 | B38: 2025.05.06 | C38: 21.88 | D38: 41 | E38: 898
A39: 34 | B39: 2025.06.06 | C39: 23 | D39: 39 | E39: 898
A40: 35 | B40: 2025.07.07 | C40: 24.53 | D40: 36 | E40: 884
... A42: 37 | B42: 2025.09.08 | C42: 24.64 | D42: 36 | E42: 888
A43: 38 | B43: 2025.09.22 | C43: 0 | D43: 153 | E43: 0 | F43: 4112
...

Sheet VT
C1: 存股統計專用表格 | F1: VT | H1: USD
A2: 實際成本 | B2: 帳面成本 | C2: 目前市價 | D2: 總股數 | E2: 總成本 | F2: 股利+借券 | G2: 報酬率(含息) | H2: 目前市價 | I2: 目前匯率 | J2: 總成本
A3: =(E3-F3)/D3 | B3: =E3/D3 | C3: =H3 | D3: =SUM(D7:D505) | E3: =SUM(E7:E505) | F3: =SUM(F6:G505) | G3: =G4/E3 | H3: 5109.4062 | I3: =投資!G2 | J3: =SUM(J7:J505)
G4: =D3*C3-E3+F3
A5: 交易筆數 | B5: 購買日期 | C5: 購入價格 | D5: 股數 | E5: 持有成本 | F5: 股利 | H5: 購入價格 | I5: 購入匯率 | J5: 購入金額
A6: 1 | B6: 借券收入
A7: 2 | B7: 2023.07.17 | C7: =H7*I7 | D7: 0.326071 | E7: 1000 | H7: 98.69 | I7: 31.075 | J7: 32.18
A8: 3 | B8: 2023.08.16 | C8: =H8*I8 | D8: 0.325535 | E8: 1000 | H8: 96.18 | I8: 31.935 | J8: 31.31
A9: 4 | B9: 2023.09.16 | C9: =H9*I9 | D9: 0.321135 | E9: 1000 | H9: 97.28 | I9: 32.013 | J9: 31.24
A10: 5 | B10: 2023.09.16 | C10: =H10*I10 | D10: 12.84426 | E10: 40004 | H10: 97.28 | I10: 32.013 | J10: 1249.49
A11: 6 | B11: 2023.09.27 | C11: =H11*I11 | F11: 126
A12: 7 | B12: 2023.10.06 | C12: =H12*I12 | D12: 0.337951 | E12: 1000 | H12: 91.61 | I12: 32.3 | J12: 30.96
A13: 8 | B13: 2023.11.06 | C13: =H13*I13 | D13: 0.328741 | E13: 1000 | H13: 94.52 | I13: 32.185 | J13: 31.07
A14: 9 | B14: 2023.12.06 | C14: =H14*I14 | D14: 0.319359 | E14: 1000 | H14: 99.23 | I14: 31.552 | J14: 31.69
A15: 10 | B15: 2023.12.28 | C15: =H15*I15 | F15: 254
A16: 11 | B16: 2024.01.08 | C16: =H16*I16 | D16: 0.318718 | E16: 1003 | H16: 101.06 | I16: 31.042 | J16: 32.21
A17: 12 | B17: 2024.02.06 | C17: =H17*I17 | D17: 0.305353 | E17: 1000 | H17: 104.24 | I17: 31.419 | J17: 31.83
A18: 13 | B18: 2024.03.06 | C18: =H18*I18 | D18: 0.291167 | E18: 1000 | H18: 108.46 | I18: 31.664 | J18: 31.58
A19: 14 | B19: 2024.03.26 | C19: =H19*I19 | F19: 148
A20: 15 | B20: 2024.04.08 | C20: =H20*I20 | D20: 0.282856 | E20: 1000 | H20: 109.95 | I20: 32.151 | J20: 31.1
A21: 16 | B21: 2024.05.06 | C21: =H21*I21 | D21: 0.282434 | E21: 1000 | H21: 109.3 | I21: 32.389 | J21: 30.87
A22: 17 | B22: 2024.06.06 | C22: =H22*I22 | D22: 0.27448 | E22: 1000 | H22: 112.54 | I22: 32.37 | J22: 30.89
A23: 18 | B23: 2024.06.28 | C23: =H23*I23 | F23: 217
A24: 19 | B24: 2024.07.08 | C24: =H24*I24 | D24: 7.77443 | E24: 29003 | H24: 114.9 | I24: 32.465 | J24: 893.27
A25: 20 | B25: 2024.08.06 | C25: =H25*I25 | D25: 0.84917 | E25: 3000 | H25: 107.74 | I25: 32.79 | J25: 91.49
A26: 21 | B26: 2024.09.06 | C26: =H26*I26 | D26: 0.8148 | E26: 3000 | H26: 114.89 | I26: 32.047 | J26: 93.61
A27: 22 | B27: 2024.09.27 | C27: =H27*I27 | F27: 241
A28: 23 | B28: 2024.10.07 | C28: =H28*I28 | D28: 0.78006 | E28: 3000 | H28: 119.31 | I28: 32.234 | J28: 93.07
A29: 24 | B29: 2024.11.06 | C29: =H29*I29 | D29: 0.7771 | E29: 3000 | H29: 120 | I29: 32.173 | J29: 93.25
A30: 25 | B30: 2024.12.06 | C30: =H30*I30 | D30: 0.7498 | E30: 3000 | H30: 123.3 | I30: 32.45 | J30: 92.45
A31: 26 | B31: 2024.12.30 | C31: =H31*I31 | F31: 568
A32: 27 | B32: 2025.01.06 | C32: =H32*I32 | D32: 0.76234 | E32: 3000 | H32: 119.39 | I32: 32.96 | J32: 91.02
A33: 28 | B33: 2025.02.06 | C33: =H33*I33 | D33: 0.74614 | E33: 3000 | H33: 122.23 | I33: 32.895 | J33: 91.2
A34: 29 | B34: 2025.03.06 | C34: =H34*I34 | D34: 0.76347 | E34: 3000 | H34: 119.39 | I34: 32.912 | J34: 91.15
A35: 30 | B35: 2025.03.28 | C35: =H35*I35 | F35: 273
A36: 31 | B36: 2025.04.07 | C36: =H36*I36 | D36: 0.88548 | E36: 3000 | H36: 102.09 | I36: 33.185 | J36: 90.4
A37: 32 | B37: 2025.05.06 | C37: =H37*I37 | D37: 0.84048 | E37: 3000 | H37: 117.98 | I37: 30.255 | J37: 99.16
A38: 33 | B38: 2025.06.06 | C38: =H38*I38 | D38: 0.79885 | E38: 3000 | H38: 125.33 | I38: 29.964 | J38: 100.12
A39: 34 | B39: 2025.06.27 | C39: =H39*I39 | F39: 398
A40: 35 | B40: 2025.07.07 | C40: =H40*I40 | D40: 1.00626 | E40: 3804.3506 | H40: 129.32 | I40: 29.235 | J40: 130.13
...

Sheet VOO
C1: 存股統計專用表格 | F1: VOO | H1: USD
A2: 實際成本 | B2: 帳面成本 | C2: 目前市價 | D2: 總股數 | E2: 總成本 | F2: 股利+借券 | G2: 報酬率(含息) | H2: 目前市價 | I2: 目前匯率 | J2: 總成本
A3: =(E3-F3)/D3 | B3: =E3/D3 | C3: =H3 | D3: =SUM(D7:D505) | E3: =SUM(E7:E505) | F3: =SUM(F6:G505) | G3: =G4/E3 | H3: 22885.477 | I3: =投資!G2 | J3: =SUM(J7:J505)
G4: =D3*C3-E3+F3
A5: 交易筆數 | B5: 購買日期 | C5: 購入價格 | D5: 股數 | E5: 持有成本 | F5: 股利 | H5: 購入價格 | I5: 購入匯率 | J5: 購入金額
A6: 1 | B6: 借券收入
A7: 2 | B7: 2026.07.06 | C7: =H7*I7 | D7: 0.24703 | E7: =J7*I7 | H7: 688.15 | I7: 31.934 | J7: 170.01
A8: 3 | B8: 2026.08.06 | C8: =H8*I8 | D8: 0.24018 | E8: =J8*I8 | H8: 707.82 | I8: 32.3526 | J8: 170.01
A9: 4 | B9: 2026.09.08 | C9: =H9*I9 | D9: 0.24045 | E9: =J9*I9 | H9: 707.03 | I9: 31.96 | J9: 170.01
A10: 5 | B10: 2026.10.06 | C10: =H10*I10 | D10: 0.23766 | E10: =J10*I10 | H10: 715.28 | I10: 31.81 | J10: 170.01
A11: 6 | C11: =H11*I11 | E11: =J11*I11
A12: 7 | C12: =H12*I12 | E12: =J12*I12
A13: 8 | C13: =H13*I13 | E13: =J13*I13
A14: 9 | C14: =H14*I14 | E14: =J14*I14
A15: 10 | C15: =H15*I15 | E15: =J15*I15
A16: 11 | C16: =H16*I16 | E16: =J16*I16
A17: 12 | C17: =H17*I17 | E17: =J17*I17
A18: 13 | C18: =H18*I18 | E18: =J18*I18
A19: 14 | C19: =H19*I19 | E19: =J19*I19
A20: 15 | C20: =H20*I20 | E20: =J20*I20
A21: 16 | C21: =H21*I21 | E21: =J21*I21
A22: 17 | C22: =H22*I22 | E22: =J22*I22
... A505: 500 | C505: =H505*I505 | E505: =J505*I505

Sheet 00692
C1: 存股統計專用表格 | F1: 00692.TW
A2: 實際成本 | B2: 帳面成本 | C2: 目前市價 | D2: 總股數 | E2: 總成本 | F2: 股利+借券 | G2: 報酬率(含息)
A3: =(E3-F3)/D3 | B3: =E3/D3 | C3: 61.25 | D3: =SUM(D7:D505) | E3: =SUM(E7:E505) | F3: =SUM(F6:G505) | G3: =G4/E3
G4: =D3*C3-E3+F3
A5: 交易筆數 | B5: 購買日期 | C5: 購入價格 | D5: 股數 | E5: 持有成本 | F5: 股利
A6: 1 | B6: 借券收入
A7: 2 | B7: 2023.08.09 | C7: 31.92 | D7: 30 | E7: 958
A8: 3 | B8: 2023.08.18 | C8: 31.18 | D8: 1000 | E8: 31224
A9: 4 | B9: 2023.09.11 | C9: 31.03 | D9: 30 | E9: 932
A10: 5 | B10: 2023.10.06 | C10: 31.12 | D10: 31 | E10: 966
A11: 6 | B11: 2023.10.24 | C11: 30.79 | D11: 50 | E11: 1541
A12: 7 | B12: 2023.11.06 | C12: 31.67 | D12: 30 | E12: 951
A13: 8 | B13: 2023.12.06 | C13: 31.67 | D13: 30 | E13: 951
A14: 9 | B14: 2023.12.12 | F14: 1234
A15: 10 | B15: 2024.01.08 | C15: 32.1 | D15: 30 | E15: 964
A16: 11 | B16: 2024.01.17 | C16: 31.57 | D16: 50 | E16: 1580
A17: 12 | B17: 2024.02.15 | C17: 34.36 | D17: 28 | E17: 863
A18: 13 | B18: 2024.03.06 | C18: 35.65 | D18: 26 | E18: 928
A19: 14 | B19: 2024.04.08 | C19: 38.24 | D19: 25 | E19: 957
A20: 15 | B20: 2024.05.06 | C20: 38.52 | D20: 25 | E20: 964
A21: 16 | B21: 2024.06.06 | C21: 41.65 | D21: 23 | E21: 959
A22: 17 | B22: 2024.07.08 | C22: 46.29 | D22: 21 | E22: 973
A23: 18 | B23: 2024.08.06 | C23: 39.24 | D23: 25 | E23: 982
A24: 19 | B24: 2024.08.09 | F24: 593
A25: 20 | B25: 2024.08.16 | C25: 43 | D25: 11 | E25: 474
A26: 21 | B26: 2024.09.06 | C26: 41.04 | D26: 24 | E26: 986
A27: 22 | B27: 2024.10.07 | C27: 43.86 | D27: 22 | E27: 965
A28: 23 | B28: 2024.11.06 | C28: 45.76 | D28: 21 | E28: 962
A29: 24 | B29: 2024.12.06 | C29: 44.95 | D29: 22 | E29: 990
A30: 25 | B30: 2024.12.12 | F30: 919
A31: 26 | B31: 2024.12.19 | C31: 44.45 | D31: 20 | E31: 890
A32: 27 | B32: 2025.01.06 | C32: 45.95 | D32: 21 | E32: 966
A33: 28 | B33: 2025.02.06 | C33: 45.67 | D33: 21 | E33: 960
A34: 29 | B34: 2025.03.06 | C34: 43.82 | D34: 22 | E34: 965
A35: 30 | B35: 2025.04.07 | C35: 37.08 | D35: 26 | E35: 965
A36: 31 | B36: 2025.05.06 | C36: 39.92 | D36: 24 | E36: 959
A37: 32 | B37: 2025.06.06 | C37: 42.22 | D37: 23 | E37: 972
A38: 33 | B38: 2025.07.07 | C38: 44.82 | D38: 22 | E38: 987
A39: 34 | B39: 2025.08.06 | C39: 46.48 | D39: 21 | E39: 977
A40: 35 | B40: 2025.08.08 | F40: 1088
...

Sheet BND
C1: 存股統計專用表格 | F1: BND | H1: USD
A2: 實際成本 | B2: 帳面成本 | C2: 目前市價 | D2: 總股數 | E2: 總成本 | F2: 股利+借券 | G2: 報酬率(含息) | H2: 目前市價 | I2: 目前匯率 | J2: 總成本
A3: =(E3-F3)/D3 | B3: =E3/D3 | C3: =H3*I3 | D3: =SUM(D7:D505) | E3: =SUM(E7:E505) | F3: =SUM(F6:G505) | G3: =G4/E3 | H3: 74.18 | I3: =投資!G2 | J3: =SUM(J7:J505)
G4: =D3*C3-E3+F3
A5: 交易筆數 | B5: 購買日期 | C5: 購入價格 | D5: 股數 | E5: 持有成本 | F5: 股利 | H5: 購入價格 | I5: 購入匯率 | J5: 購入金額
A6: 1 | B6: 借券收入
A7: 2 | B7: 2023.07.17 | C7: =H7*I7 | D7: 0.443373 | E7: 1000 | H7: 72.58 | I7: 31.075 | J7: 32.18
A8: 3 | B8: 2023.08.10 | C8: =H8*I8 | F8: 2
A9: 4 | B9: 2023.08.16 | C9: =H9*I9 | D9: 0.441048 | E9: 1000 | H9: 70.99 | I9: 31.935 | J9: 31.31
A10: 5 | B10: 2023.09.06 | C10: =H10*I10 | D10: 0.440621 | E10: 1000 | H10: 70.9 | I10: 32.013 | J10: 31.24
A11: 6 | B11: 2023.09.06 | C11: =H11*I11 | D11: 4.405785 | E11: 10001 | H11: 70.9 | I11: 32.013 | J11: 312.37
A12: 7 | B12: 2023.09.13 | C12: =H12*I12 | F12: 4
A13: 8 | B13: 2023.10.06 | C13: =H13*I13 | D13: 0.451706 | E13: 1000 | H13: 68.54 | I13: 32.3 | J13: 30.96
A14: 9 | B14: 2023.10.12 | C14: =H14*I14 | F14: 25
A15: 10 | B15: 2023.11.06 | C15: =H15*I15 | D15: 0.446087 | E15: 1000 | H15: 69.65 | I15: 32.185 | J15: 31.07
A16: 11 | B16: 2023.11.10 | C16: =H16*I16 | F16: 28
A17: 12 | B17: 2023.12.06 | C17: =H17*I17 | D17: 0.439224 | E17: 1000 | H17: 72.15 | I17: 31.552 | J17: 31.69
A18: 13 | B18: 2023.12.12 | C18: =H18*I18 | F18: 29
A19: 14 | B19: 2024.01.03 | C19: =H19*I19 | F19: 32
A20: 15 | B20: 2024.01.08 | C20: =H20*I20 | D20: 0.442402 | E20: 1003 | H20: 72.83 | I20: 31.042 | J20: 32.22
A21: 16 | B21: 2024.02.06 | C21: =H21*I21 | D21: 0.438853 | E21: 1000 | H21: 72.53 | I21: 31.419 | J21: 31.83
A22: 17 | B22: 2024.02.16 | C22: =H22*I22 | F22: 35
A23: 18 | B23: 2024.03.06 | C23: =H23*I23 | D23: 0.434866 | E23: 1000 | H23: 72.62 | I23: 31.664 | J23: 31.58
A24: 19 | B24: 2024.03.12 | C24: =H24*I24 | F24: 35
A25: 20 | B25: 2024.04.08 | C25: =H25*I25 | D25: 0.434236 | E25: 1000 | H25: 71.62 | I25: 32.151 | J25: 31.1
A26: 21 | B26: 2024.04.10 | C26: =H26*I26 | F26: 41
A27: 22 | B27: 2024.05.06 | C27: =H27*I27 | D27: 0.432494 | E27: 1000 | H27: 71.4 | I27: 32.389 | J27: 30.88
A28: 23 | B28: 2024.05.10 | C28: =H28*I28 | F28: 43
A29: 24 | B29: 2024.06.06 | C29: =H29*I29 | D29: 0.42778 | E29: 1000 | H29: 72.21 | I29: 32.37 | J29: 30.89
A30: 25 | B30: 2024.06.11 | C30: =H30*I30 | F30: 46
A31: 26 | B31: 2024.07.08 | C31: =H31*I31 | D31: 0.42549 | E31: 1000 | H31: 72.39 | I31: 32.465 | J31: 30.8
A32: 27 | B32: 2024.07.09 | C32: =H32*I32 | F32: 48
A33: 28 | B33: 2024.08.06 | C33: =H33*I33 | D33: 0.41078 | E33: 1000 | H33: 74.25 | I33: 32.79 | J33: 30.5
A34: 29 | B34: 2024.08.08 | C34: =H34*I34 | F34: 51
A35: 30 | B35: 2024.09.06 | C35: =H35*I35 | D35: 0.41619 | E35: 1000 | H35: 74.99 | I35: 32.047 | J35: 31.21
A36: 31 | B36: 2024.09.09 | C36: =H36*I36 | F36: 53
A37: 32 | B37: 2024.10.07 | C37: =H37*I37 | D37: 0.41966 | E37: 1000 | H37: 73.92 | I37: 32.234 | J37: 31.02
A38: 33 | B38: 2024.10.08 | C38: =H38*I38 | F38: 54
A39: 34 | B39: 2024.11.06 | C39: =H39*I39 | D39: 0.42988 | E39: 1000 | H39: 72.3 | I39: 32.173 | J39: 31.08
A40: 35 | B40: 2024.11.08 | C40: =H40*I40 | F40: 58
...
